Workbook

Sheet RATS Entry Import
A1: Entry_ID | B1: Robot | C1: C_ID | D1: Contest | E1: Challenge | F1: Class | G1: Source | H1: Contestant | I1: Cont_Level | J1: Team_Information
A2: 10001 | B2: Example Robot 01 | C2: 9001 | D2: Junior Line Follower | E2: Half Size Line Follower | F2: Final | G2: OnLineForm | H2: Example Contestant 01 | I2: Junior
A3: 10002 | B3: Example Robot 02 | C3: 9001 | D3: Junior Line Follower | E3: Half Size Line Follower | F3: Final | G3: OnLineForm | H3: Example Contestant 02 | I3: Junior
A4: 10003 | B4: Example Robot 03 | C4: 9001 | D4: Junior Line Follower | E4: Half Size Line Follower | F4: Final | G4: OnLineForm | H4: Example Contestant 03 | I4: Junior
A5: 10004 | B5: Example Robot 04 | C5: 9002 | D5: Senior Line Follower | E5: Half Size Line Follower | F5: Final | G5: OnLineForm | H5: Example Contestant 04 | I5: Senior
A6: 10005 | B6: Example Robot 05 | C6: 9002 | D6: Senior Line Follower | E6: Half Size Line Follower | F6: Final | G6: OnLineForm | H6: Example Contestant 05 | I6: Senior
A7: 10006 | B7: Example Robot 06 | C7: 9002 | D7: Senior Line Follower | E7: Half Size Line Follower | F7: Final | G7: OnLineForm | H7: Example Contestant 06 | I7: Senior
A8: 10007 | B8: Example Robot 07 | C8: 9002 | D8: Senior Line Follower | E8: Half Size Line Follower | F8: Final | G8: OnLineForm | H8: Example Contestant 07 | I8: Senior
A9: 10008 | B9: Example Robot 08 | C9: 9002 | D9: Senior Line Follower | E9: Half Size Line Follower | F9: Final | G9: OnLineForm | H9: Example Contestant 07 | I9: Senior
A10: 10009 | B10: Example Robot 09 | C10: 9002 | D10: Senior Line Follower | E10: Half Size Line Follower | F10: Final | G10: OnLineForm | H10: Example Contestant 08 | I10: Senior
A11: 10010 | B11: Example Robot 10 | C11: 9002 | D11: Senior Line Follower | E11: Half Size Line Follower | F11: Final | G11: OnLineForm | H11: Example Contestant 09 | I11: Senior
A12: 10011 | B12: Example Robot 11 | C12: 9002 | D12: Senior Line Follower | E12: Half Size Line Follower | F12: Final | G12: OnLineForm | H12: Example Contestant 09 | I12: Senior
A13: 10012 | B13: Example Robot 12 | C13: 9002 | D13: Senior Line Follower | E13: Half Size Line Follower | F13: Final | G13: OnLineForm | H13: Example Contestant 05 | I13: Senior
... A72: 10071 | B72: Example Robot 59 | C72: 9009 | D72: Half Size Maze Solver | E72: Half Size Maze Solver | F72: Final | G72: OnLineForm | H72: Example Contestant 06 | I72: Senior

Sheet Value Copied Summary
A2: JUNIOR | B2: Line Follower | C2: Half Size LF | D2: Drag Race | E2: Wall Follower | F2: Half WF | G2: Maze Solver | H2: Half Maze Solver | I2: Pursuit
B3: =SUM('RobotLookup Clean'!$Q$2:$Q$1001) -> 0 | C3: =SUM('RobotLookup Clean'!$R$2:$R$1001) -> 3 | D3: =SUM('RobotLookup Clean'!$S$2:$S$1001) -> 0 | E3: =SUM('RobotLookup Clean'!$T$2:$T$1001) -> 2 | F3: =SUM('RobotLookup Clean'!$U$2:$U$1001) -> 0 | G3: =SUM('RobotLookup Clean'!$V$2:$V$1001) -> 1 | H3: =SUM('RobotLookup Clean'!$W$2:$W$1001) -> 0 | I3: =SUM('RobotLookup Clean'!$X$2:$X$1001) -> 0 | J3: =SUM(B3:I3) -> 6
J4: =SUM(B4:I4) -> 0
A6: SENIOR
B7: Line Follower | C7: Half Size LF | D7: Drag Race | E7: Wall Follower | F7: Half WF | G7: Maze Solver | H7: Half Maze Solver | I7: Pursuit
B8: =SUM('RobotLookup Clean'!$Y$2:$Y$1001) -> 0 | C8: =SUM('RobotLookup Clean'!$Z$2:$Z$1001) -> 12 | D8: =SUM('RobotLookup Clean'!$AA$2:$AA$1001) -> 6 | E8: =SUM('RobotLookup Clean'!$AB$2:$AB$1001) -> 12 | F8: =SUM('RobotLookup Clean'!$AC$2:$AC$1001) -> 7 | G8: =SUM('RobotLookup Clean'!$AD$2:$AD$1001) -> 23 | H8: =SUM('RobotLookup Clean'!$AE$2:$AE$1001) -> 5 | I8: =SUM('RobotLookup Clean'!$AF$2:$AF$1001) -> 0 | J8: =SUM(B8:I8) -> 65
J9: =SUM(B9:I9) -> 0
A11: TOTAL | B11: =B8+B3 -> 0 | C11: =C8+C3 -> 15 | D11: =D8+D3 -> 6 | E11: =E8+E3 -> 14 | F11: =F8+F3 -> 7 | G11: =G8+G3 -> 24 | H11: =H8+H3 -> 5 | I11: =I8+I3 -> 0 | J11: =J8+J3 -> 71
B13: Total Entries | D13: =J8+J3 -> 71
B14: Recorded Entries | D14: =J9+J4 -> 0
B16: Imported entry rows | D16: =COUNT('RobotLookup Clean'!$AJ$2:$AJ$1001) -> 71
B17: Entries requiring attention | D17: =COUNTIF('RobotLookup Clean'!$A$2:$A$1001,"?*")-COUNTIF('RobotLookup Clean'!$A$2:$A$1001,"OK") -> 0
B18: Nonblank cells beyond capacity | D18: =COUNTA('RATS Entry Import'!$A$1002:$J$1048576) -> 0
B19: Duplicate entry IDs | D19: =SUMPRODUCT(('RATS Entry Import'!$A$2:$A$1001<>"")*(COUNTIF('RATS Entry Import'!$A$2:$A$1001,'RATS Entry Import'!$A$2:$A$1001)>1)) -> 0
B21: Paste CSV into RATS Entry Import; clear old data first.
B22: Recalculate (Ctrl+Alt+F9), save, and check the validation counts above.
B23: Email is not supplied. Class=Final is source metadata; Cont_Level selects Junior/Senior.
B24: Each row represents one contest entry. Event Mapping translates Challenge names.

Sheet RobotLookup Clean
A1: Validation | B1: Robot | C1: Challenge | D1: Builder | E1: Level | F1: Email | G1: Entry ID | H1: LF | I1: HLF | J1: DR | K1: WF | L1: HWF | M1: MS | N1: HMS | O1: PUR | Q1: JLF | R1: JHLF | S1: JDR | T1: JWF | U1: JHWF | V1: JMS | W1: JHMS | X1: JPUR | Y1: SLF | Z1: SHLF | AA1: SDR | AB1: SWF | AC1: SHWF | AD1: SMS | AE1: SHMS | AF1: SPUR | AG1: Challenge Count | AH1: Contest Count | AI1: Difference | AJ1: Source Row | AK1: Event Code | AL1: Contest | AM1: C_ID | AN1: Source Class | AO1: Source | AP1: Team Information
A2: =IF($AJ2="","",IF(OR($G2="",$B2="",$D2=""),"MISSING DETAILS",IF(AND($E2<>"Junior",$E2<>"Senior"),"INVALID LEVEL",IF($AH2<>1,"UNMAPPED CHALLENGE","OK")))) -> OK | B2: =IF($AJ2="","",IF('RATS Entry Import'!B2="","",'RATS Entry Import'!B2)) -> Example Robot 01 | C2: =IF($AJ2="","",IF('RATS Entry Import'!E2="","",'RATS Entry Import'!E2)) -> Half Size Line Follower | D2: =IF($AJ2="","",IF('RATS Entry Import'!H2="","",'RATS Entry Import'!H2)) -> Example Contestant 01 | E2: =IF($AJ2="","",IF('RATS Entry Import'!I2="","",'RATS Entry Import'!I2)) -> Junior | F2: =IF($AJ2="","","") | G2: =IF($AJ2="","",IF('RATS Entry Import'!A2="","",'RATS Entry Import'!A2)) -> 10001 | H2: =IF($AJ2="","",IF($AK2="LF",1,0)) -> 0 | I2: =IF($AJ2="","",IF($AK2="HLF",1,0)) -> 1 | J2: =IF($AJ2="","",IF($AK2="DR",1,0)) -> 0 | K2: =IF($AJ2="","",IF($AK2="WF",1,0)) -> 0 | L2: =IF($AJ2="","",IF($AK2="HWF",1,0)) -> 0 | M2: =IF($AJ2="","",IF($AK2="MS",1,0)) -> 0 | N2: =IF($AJ2="","",IF($AK2="HMS",1,0)) -> 0 | O2: =IF($AJ2="","",IF($AK2="PUR",1,0)) -> 0 | Q2: =IF(AND($AJ2<>"",$E2="Junior",H2>0),H2,"") | R2: =IF(AND($AJ2<>"",$E2="Junior",I2>0),I2,"") -> 1 | S2: =IF(AND($AJ2<>"",$E2="Junior",J2>0),J2,"") | T2: =IF(AND($AJ2<>"",$E2="Junior",K2>0),K2,"") | U2: =IF(AND($AJ2<>"",$E2="Junior",L2>0),L2,"") | V2: =IF(AND($AJ2<>"",$E2="Junior",M2>0),M2,"") | W2: =IF(AND($AJ2<>"",$E2="Junior",N2>0),N2,"") | X2: =IF(AND($AJ2<>"",$E2="Junior",O2>0),O2,"") | Y2: =IF(AND($AJ2<>"",$E2="Senior",H2>0),H2,"") | Z2: =IF(AND($AJ2<>"",$E2="Senior",I2>0),I2,"") | AA2: =IF(AND($AJ2<>"",$E2="Senior",J2>0),J2,"") | AB2: =IF(AND($AJ2<>"",$E2="Senior",K2>0),K2,"") | AC2: =IF(AND($AJ2<>"",$E2="Senior",L2>0),L2,"") | AD2: =IF(AND($AJ2<>"",$E2="Senior",M2>0),M2,"") | AE2: =IF(AND($AJ2<>"",$E2="Senior",N2>0),N2,"") | AF2: =IF(AND($AJ2<>"",$E2="Senior",O2>0),O2,"") | AG2: =IF($AJ2="","",SUM(H2:O2)) -> 1 | AH2: =IF($AJ2="","",SUM(Q2:AF2)) -> 1 | AI2: =IF($AJ2="","",AG2-AH2) -> 0 | AJ2: =IF(COUNTA('RATS Entry Import'!A2:J2)=0,"",ROW()) -> 2 | AK2: =IF($AJ2="","",IFERROR(VLOOKUP($C2,'Event Mapping'!$A$2:$B$100,2,FALSE),"UNMAPPED")) -> HLF | AL2: =IF($AJ2="","",IF('RATS Entry Import'!D2="","",'RATS Entry Import'!D2)) -> Junior Line Follower | AM2: =IF($AJ2="","",IF('RATS Entry Import'!C2="","",'RATS Entry Import'!C2)) -> 9001 | AN2: =IF($AJ2="","",IF('RATS Entry Import'!F2="","",'RATS Entry Import'!F2)) -> Final | AO2: =IF($AJ2="","",IF('RATS Entry Import'!G2="","",'RATS Entry Import'!G2)) -> OnLineForm | AP2: =IF($AJ2="","",IF('RATS Entry Import'!J2="","",'RATS Entry Import'!J2))
A3: =IF($AJ3="","",IF(OR($G3="",$B3="",$D3=""),"MISSING DETAILS",IF(AND($E3<>"Junior",$E3<>"Senior"),"INVALID LEVEL",IF($AH3<>1,"UNMAPPED CHALLENGE","OK")))) -> OK | B3: =IF($AJ3="","",IF('RATS Entry Import'!B3="","",'RATS Entry Import'!B3)) -> Example Robot 02 | C3: =IF($AJ3="","",IF('RATS Entry Import'!E3="","",'RATS Entry Import'!E3)) -> Half Size Line Follower | D3: =IF($AJ3="","",IF('RATS Entry Import'!H3="","",'RATS Entry Import'!H3)) -> Example Contestant 02 | E3: =IF($AJ3="","",IF('RATS Entry Import'!I3="","",'RATS Entry Import'!I3)) -> Junior | F3: =IF($AJ3="","","") | G3: =IF($AJ3="","",IF('RATS Entry Import'!A3="","",'RATS Entry Import'!A3)) -> 10002 | H3: =IF($AJ3="","",IF($AK3="LF",1,0)) -> 0 | I3: =IF($AJ3="","",IF($AK3="HLF",1,0)) -> 1 | J3: =IF($AJ3="","",IF($AK3="DR",1,0)) -> 0 | K3: =IF($AJ3="","",IF($AK3="WF",1,0)) -> 0 | L3: =IF($AJ3="","",IF($AK3="HWF",1,0)) -> 0 | M3: =IF($AJ3="","",IF($AK3="MS",1,0)) -> 0 | N3: =IF($AJ3="","",IF($AK3="HMS",1,0)) -> 0 | O3: =IF($AJ3="","",IF($AK3="PUR",1,0)) -> 0 | Q3: =IF(AND($AJ3<>"",$E3="Junior",H3>0),H3,"") | R3: =IF(AND($AJ3<>"",$E3="Junior",I3>0),I3,"") -> 1 | S3: =IF(AND($AJ3<>"",$E3="Junior",J3>0),J3,"") | T3: =IF(AND($AJ3<>"",$E3="Junior",K3>0),K3,"") | U3: =IF(AND($AJ3<>"",$E3="Junior",L3>0),L3,"") | V3: =IF(AND($AJ3<>"",$E3="Junior",M3>0),M3,"") | W3: =IF(AND($AJ3<>"",$E3="Junior",N3>0),N3,"") | X3: =IF(AND($AJ3<>"",$E3="Junior",O3>0),O3,"") | Y3: =IF(AND($AJ3<>"",$E3="Senior",H3>0),H3,"") | Z3: =IF(AND($AJ3<>"",$E3="Senior",I3>0),I3,"") | AA3: =IF(AND($AJ3<>"",$E3="Senior",J3>0),J3,"") | AB3: =IF(AND($AJ3<>"",$E3="Senior",K3>0),K3,"") | AC3: =IF(AND($AJ3<>"",$E3="Senior",L3>0),L3,"") | AD3: =IF(AND($AJ3<>"",$E3="Senior",M3>0),M3,"") | AE3: =IF(AND($AJ3<>"",$E3="Senior",N3>0),N3,"") | AF3: =IF(AND($AJ3<>"",$E3="Senior",O3>0),O3,"") | AG3: =IF($AJ3="","",SUM(H3:O3)) -> 1 | AH3: =IF($AJ3="","",SUM(Q3:AF3)) -> 1 | AI3: =IF($AJ3="","",AG3-AH3) -> 0 | AJ3: =IF(COUNTA('RATS Entry Import'!A3:J3)=0,"",ROW()) -> 3 | AK3: =IF($AJ3="","",IFERROR(VLOOKUP($C3,'Event Mapping'!$A$2:$B$100,2,FALSE),"UNMAPPED")) -> HLF | AL3: =IF($AJ3="","",IF('RATS Entry Import'!D3="","",'RATS Entry Import'!D3)) -> Junior Line Follower | AM3: =IF($AJ3="","",IF('RATS Entry Import'!C3="","",'RATS Entry Import'!C3)) -> 9001 | AN3: =IF($AJ3="","",IF('RATS Entry Import'!F3="","",'RATS Entry Import'!F3)) -> Final | AO3: =IF($AJ3="","",IF('RATS Entry Import'!G3="","",'RATS Entry Import'!G3)) -> OnLineForm | AP3: =IF($AJ3="","",IF('RATS Entry Import'!J3="","",'RATS Entry Import'!J3))
A4: =IF($AJ4="","",IF(OR($G4="",$B4="",$D4=""),"MISSING DETAILS",IF(AND($E4<>"Junior",$E4<>"Senior"),"INVALID LEVEL",IF($AH4<>1,"UNMAPPED CHALLENGE","OK")))) -> OK | B4: =IF($AJ4="","",IF('RATS Entry Import'!B4="","",'RATS Entry Import'!B4)) -> Example Robot 03 | C4: =IF($AJ4="","",IF('RATS Entry Import'!E4="","",'RATS Entry Import'!E4)) -> Half Size Line Follower | D4: =IF($AJ4="","",IF('RATS Entry Import'!H4="","",'RATS Entry Import'!H4)) -> Example Contestant 03 | E4: =IF($AJ4="","",IF('RATS Entry Import'!I4="","",'RATS Entry Import'!I4)) -> Junior | F4: =IF($AJ4="","","") | G4: =IF($AJ4="","",IF('RATS Entry Import'!A4="","",'RATS Entry Import'!A4)) -> 10003 | H4: =IF($AJ4="","",IF($AK4="LF",1,0)) -> 0 | I4: =IF($AJ4="","",IF($AK4="HLF",1,0)) -> 1 | J4: =IF($AJ4="","",IF($AK4="DR",1,0)) -> 0 | K4: =IF($AJ4="","",IF($AK4="WF",1,0)) -> 0 | L4: =IF($AJ4="","",IF($AK4="HWF",1,0)) -> 0 | M4: =IF($AJ4="","",IF($AK4="MS",1,0)) -> 0 | N4: =IF($AJ4="","",IF($AK4="HMS",1,0)) -> 0 | O4: =IF($AJ4="","",IF($AK4="PUR",1,0)) -> 0 | Q4: =IF(AND($AJ4<>"",$E4="Junior",H4>0),H4,"") | R4: =IF(AND($AJ4<>"",$E4="Junior",I4>0),I4,"") -> 1 | S4: =IF(AND($AJ4<>"",$E4="Junior",J4>0),J4,"") | T4: =IF(AND($AJ4<>"",$E4="Junior",K4>0),K4,"") | U4: =IF(AND($AJ4<>"",$E4="Junior",L4>0),L4,"") | V4: =IF(AND($AJ4<>"",$E4="Junior",M4>0),M4,"") | W4: =IF(AND($AJ4<>"",$E4="Junior",N4>0),N4,"") | X4: =IF(AND($AJ4<>"",$E4="Junior",O4>0),O4,"") | Y4: =IF(AND($AJ4<>"",$E4="Senior",H4>0),H4,"") | Z4: =IF(AND($AJ4<>"",$E4="Senior",I4>0),I4,"") | AA4: =IF(AND($AJ4<>"",$E4="Senior",J4>0),J4,"") | AB4: =IF(AND($AJ4<>"",$E4="Senior",K4>0),K4,"") | AC4: =IF(AND($AJ4<>"",$E4="Senior",L4>0),L4,"") | AD4: =IF(AND($AJ4<>"",$E4="Senior",M4>0),M4,"") | AE4: =IF(AND($AJ4<>"",$E4="Senior",N4>0),N4,"") | AF4: =IF(AND($AJ4<>"",$E4="Senior",O4>0),O4,"") | AG4: =IF($AJ4="","",SUM(H4:O4)) -> 1 | AH4: =IF($AJ4="","",SUM(Q4:AF4)) -> 1 | AI4: =IF($AJ4="","",AG4-AH4) -> 0 | AJ4: =IF(COUNTA('RATS Entry Import'!A4:J4)=0,"",ROW()) -> 4 | AK4: =IF($AJ4="","",IFERROR(VLOOKUP($C4,'Event Mapping'!$A$2:$B$100,2,FALSE),"UNMAPPED")) -> HLF | AL4: =IF($AJ4="","",IF('RATS Entry Import'!D4="","",'RATS Entry Import'!D4)) -> Junior Line Follower | AM4: =IF($AJ4="","",IF('RATS Entry Import'!C4="","",'RATS Entry Import'!C4)) -> 9001 | AN4: =IF($AJ4="","",IF('RATS Entry Import'!F4="","",'RATS Entry Import'!F4)) -> Final | AO4: =IF($AJ4="","",IF('RATS Entry Import'!G4="","",'RATS Entry Import'!G4)) -> OnLineForm | AP4: =IF($AJ4="","",IF('RATS Entry Import'!J4="","",'RATS Entry Import'!J4))
A5: =IF($AJ5="","",IF(OR($G5="",$B5="",$D5=""),"MISSING DETAILS",IF(AND($E5<>"Junior",$E5<>"Senior"),"INVALID LEVEL",IF($AH5<>1,"UNMAPPED CHALLENGE","OK")))) -> OK | B5: =IF($AJ5="","",IF('RATS Entry Import'!B5="","",'RATS Entry Import'!B5)) -> Example Robot 04 | C5: =IF($AJ5="","",IF('RATS Entry Import'!E5="","",'RATS Entry Import'!E5)) -> Half Size Line Follower | D5: =IF($AJ5="","",IF('RATS Entry Import'!H5="","",'RATS Entry Import'!H5)) -> Example Contestant 04 | E5: =IF($AJ5="","",IF('RATS Entry Import'!I5="","",'RATS Entry Import'!I5)) -> Senior | F5: =IF($AJ5="","","") | G5: =IF($AJ5="","",IF('RATS Entry Import'!A5="","",'RATS Entry Import'!A5)) -> 10004 | H5: =IF($AJ5="","",IF($AK5="LF",1,0)) -> 0 | I5: =IF($AJ5="","",IF($AK5="HLF",1,0)) -> 1 | J5: =IF($AJ5="","",IF($AK5="DR",1,0)) -> 0 | K5: =IF($AJ5="","",IF($AK5="WF",1,0)) -> 0 | L5: =IF($AJ5="","",IF($AK5="HWF",1,0)) -> 0 | M5: =IF($AJ5="","",IF($AK5="MS",1,0)) -> 0 | N5: =IF($AJ5="","",IF($AK5="HMS",1,0)) -> 0 | O5: =IF($AJ5="","",IF($AK5="PUR",1,0)) -> 0 | Q5: =IF(AND($AJ5<>"",$E5="Junior",H5>0),H5,"") | R5: =IF(AND($AJ5<>"",$E5="Junior",I5>0),I5,"") | S5: =IF(AND($AJ5<>"",$E5="Junior",J5>0),J5,"") | T5: =IF(AND($AJ5<>"",$E5="Junior",K5>0),K5,"") | U5: =IF(AND($AJ5<>"",$E5="Junior",L5>0),L5,"") | V5: =IF(AND($AJ5<>"",$E5="Junior",M5>0),M5,"") | W5: =IF(AND($AJ5<>"",$E5="Junior",N5>0),N5,"") | X5: =IF(AND($AJ5<>"",$E5="Junior",O5>0),O5,"") | Y5: =IF(AND($AJ5<>"",$E5="Senior",H5>0),H5,"") | Z5: =IF(AND($AJ5<>"",$E5="Senior",I5>0),I5,"") -> 1 | AA5: =IF(AND($AJ5<>"",$E5="Senior",J5>0),J5,"") | AB5: =IF(AND($AJ5<>"",$E5="Senior",K5>0),K5,"") | AC5: =IF(AND($AJ5<>"",$E5="Senior",L5>0),L5,"") | AD5: =IF(AND($AJ5<>"",$E5="Senior",M5>0),M5,"") | AE5: =IF(AND($AJ5<>"",$E5="Senior",N5>0),N5,"") | AF5: =IF(AND($AJ5<>"",$E5="Senior",O5>0),O5,"") | AG5: =IF($AJ5="","",SUM(H5:O5)) -> 1 | AH5: =IF($AJ5="","",SUM(Q5:AF5)) -> 1 | AI5: =IF($AJ5="","",AG5-AH5) -> 0 | AJ5: =IF(COUNTA('RATS Entry Import'!A5:J5)=0,"",ROW()) -> 5 | AK5: =IF($AJ5="","",IFERROR(VLOOKUP($C5,'Event Mapping'!$A$2:$B$100,2,FALSE),"UNMAPPED")) -> HLF | AL5: =IF($AJ5="","",IF('RATS Entry Import'!D5="","",'RATS Entry Import'!D5)) -> Senior Line Follower | AM5: =IF($AJ5="","",IF('RATS Entry Import'!C5="","",'RATS Entry Import'!C5)) -> 9002 | AN5: =IF($AJ5="","",IF('RATS Entry Import'!F5="","",'RATS Entry Import'!F5)) -> Final | AO5: =IF($AJ5="","",IF('RATS Entry Import'!G5="","",'RATS Entry Import'!G5)) -> OnLineForm | AP5: =IF($AJ5="","",IF('RATS Entry Import'!J5="","",'RATS Entry Import'!J5))
A6: =IF($AJ6="","",IF(OR($G6="",$B6="",$D6=""),"MISSING DETAILS",IF(AND($E6<>"Junior",$E6<>"Senior"),"INVALID LEVEL",IF($AH6<>1,"UNMAPPED CHALLENGE","OK")))) -> OK | B6: =IF($AJ6="","",IF('RATS Entry Import'!B6="","",'RATS Entry Import'!B6)) -> Example Robot 05 | C6: =IF($AJ6="","",IF('RATS Entry Import'!E6="","",'RATS Entry Import'!E6)) -> Half Size Line Follower | D6: =IF($AJ6="","",IF('RATS Entry Import'!H6="","",'RATS Entry Import'!H6)) -> Example Contestant 05 | E6: =IF($AJ6="","",IF('RATS Entry Import'!I6="","",'RATS Entry Import'!I6)) -> Senior | F6: =IF($AJ6="","","") | G6: =IF($AJ6="","",IF('RATS Entry Import'!A6="","",'RATS Entry Import'!A6)) -> 10005 | H6: =IF($AJ6="","",IF($AK6="LF",1,0)) -> 0 | I6: =IF($AJ6="","",IF($AK6="HLF",1,0)) -> 1 | J6: =IF($AJ6="","",IF($AK6="DR",1,0)) -> 0 | K6: =IF($AJ6="","",IF($AK6="WF",1,0)) -> 0 | L6: =IF($AJ6="","",IF($AK6="HWF",1,0)) -> 0 | M6: =IF($AJ6="","",IF($AK6="MS",1,0)) -> 0 | N6: =IF($AJ6="","",IF($AK6="HMS",1,0)) -> 0 | O6: =IF($AJ6="","",IF($AK6="PUR",1,0)) -> 0 | Q6: =IF(AND($AJ6<>"",$E6="Junior",H6>0),H6,"") | R6: =IF(AND($AJ6<>"",$E6="Junior",I6>0),I6,"") | S6: =IF(AND($AJ6<>"",$E6="Junior",J6>0),J6,"") | T6: =IF(AND($AJ6<>"",$E6="Junior",K6>0),K6,"") | U6: =IF(AND($AJ6<>"",$E6="Junior",L6>0),L6,"") | V6: =IF(AND($AJ6<>"",$E6="Junior",M6>0),M6,"") | W6: =IF(AND($AJ6<>"",$E6="Junior",N6>0),N6,"") | X6: =IF(AND($AJ6<>"",$E6="Junior",O6>0),O6,"") | Y6: =IF(AND($AJ6<>"",$E6="Senior",H6>0),H6,"") | Z6: =IF(AND($AJ6<>"",$E6="Senior",I6>0),I6,"") -> 1 | AA6: =IF(AND($AJ6<>"",$E6="Senior",J6>0),J6,"") | AB6: =IF(AND($AJ6<>"",$E6="Senior",K6>0),K6,"") | AC6: =IF(AND($AJ6<>"",$E6="Senior",L6>0),L6,"") | AD6: =IF(AND($AJ6<>"",$E6="Senior",M6>0),M6,"") | AE6: =IF(AND($AJ6<>"",$E6="Senior",N6>0),N6,"") | AF6: =IF(AND($AJ6<>"",$E6="Senior",O6>0),O6,"") | AG6: =IF($AJ6="","",SUM(H6:O6)) -> 1 | AH6: =IF($AJ6="","",SUM(Q6:AF6)) -> 1 | AI6: =IF($AJ6="","",AG6-AH6) -> 0 | AJ6: =IF(COUNTA('RATS Entry Import'!A6:J6)=0,"",ROW()) -> 6 | AK6: =IF($AJ6="","",IFERROR(VLOOKUP($C6,'Event Mapping'!$A$2:$B$100,2,FALSE),"UNMAPPED")) -> HLF | AL6: =IF($AJ6="","",IF('RATS Entry Import'!D6="","",'RATS Entry Import'!D6)) -> Senior Line Follower | AM6: =IF($AJ6="","",IF('RATS Entry Import'!C6="","",'RATS Entry Import'!C6)) -> 9002 | AN6: =IF($AJ6="","",IF('RATS Entry Import'!F6="","",'RATS Entry Import'!F6)) -> Final | AO6: =IF($AJ6="","",IF('RATS Entry Import'!G6="","",'RATS Entry Import'!G6)) -> OnLineForm | AP6: =IF($AJ6="","",IF('RATS Entry Import'!J6="","",'RATS Entry Import'!J6))
A7: =IF($AJ7="","",IF(OR($G7="",$B7="",$D7=""),"MISSING DETAILS",IF(AND($E7<>"Junior",$E7<>"Senior"),"INVALID LEVEL",IF($AH7<>1,"UNMAPPED CHALLENGE","OK")))) -> OK | B7: =IF($AJ7="","",IF('RATS Entry Import'!B7="","",'RATS Entry Import'!B7)) -> Example Robot 06 | C7: =IF($AJ7="","",IF('RATS Entry Import'!E7="","",'RATS Entry Import'!E7)) -> Half Size Line Follower | D7: =IF($AJ7="","",IF('RATS Entry Import'!H7="","",'RATS Entry Import'!H7)) -> Example Contestant 06 | E7: =IF($AJ7="","",IF('RATS Entry Import'!I7="","",'RATS Entry Import'!I7)) -> Senior | F7: =IF($AJ7="","","") | G7: =IF($AJ7="","",IF('RATS Entry Import'!A7="","",'RATS Entry Import'!A7)) -> 10006 | H7: =IF($AJ7="","",IF($AK7="LF",1,0)) -> 0 | I7: =IF($AJ7="","",IF($AK7="HLF",1,0)) -> 1 | J7: =IF($AJ7="","",IF($AK7="DR",1,0)) -> 0 | K7: =IF($AJ7="","",IF($AK7="WF",1,0)) -> 0 | L7: =IF($AJ7="","",IF($AK7="HWF",1,0)) -> 0 | M7: =IF($AJ7="","",IF($AK7="MS",1,0)) -> 0 | N7: =IF($AJ7="","",IF($AK7="HMS",1,0)) -> 0 | O7: =IF($AJ7="","",IF($AK7="PUR",1,0)) -> 0 | Q7: =IF(AND($AJ7<>"",$E7="Junior",H7>0),H7,"") | R7: =IF(AND($AJ7<>"",$E7="Junior",I7>0),I7,"") | S7: =IF(AND($AJ7<>"",$E7="Junior",J7>0),J7,"") | T7: =IF(AND($AJ7<>"",$E7="Junior",K7>0),K7,"") | U7: =IF(AND($AJ7<>"",$E7="Junior",L7>0),L7,"") | V7: =IF(AND($AJ7<>"",$E7="Junior",M7>0),M7,"") | W7: =IF(AND($AJ7<>"",$E7="Junior",N7>0),N7,"") | X7: =IF(AND($AJ7<>"",$E7="Junior",O7>0),O7,"") | Y7: =IF(AND($AJ7<>"",$E7="Senior",H7>0),H7,"") | Z7: =IF(AND($AJ7<>"",$E7="Senior",I7>0),I7,"") -> 1 | AA7: =IF(AND($AJ7<>"",$E7="Senior",J7>0),J7,"") | AB7: =IF(AND($AJ7<>"",$E7="Senior",K7>0),K7,"") | AC7: =IF(AND($AJ7<>"",$E7="Senior",L7>0),L7,"") | AD7: =IF(AND($AJ7<>"",$E7="Senior",M7>0),M7,"") | AE7: =IF(AND($AJ7<>"",$E7="Senior",N7>0),N7,"") | AF7: =IF(AND($AJ7<>"",$E7="Senior",O7>0),O7,"") | AG7: =IF($AJ7="","",SUM(H7:O7)) -> 1 | AH7: =IF($AJ7="","",SUM(Q7:AF7)) -> 1 | AI7: =IF($AJ7="","",AG7-AH7) -> 0 | AJ7: =IF(COUNTA('RATS Entry Import'!A7:J7)=0,"",ROW()) -> 7 | AK7: =IF($AJ7="","",IFERROR(VLOOKUP($C7,'Event Mapping'!$A$2:$B$100,2,FALSE),"UNMAPPED")) -> HLF | AL7: =IF($AJ7="","",IF('RATS Entry Import'!D7="","",'RATS Entry Import'!D7)) -> Senior Line Follower | AM7: =IF($AJ7="","",IF('RATS Entry Import'!C7="","",'RATS Entry Import'!C7)) -> 9002 | AN7: =IF($AJ7="","",IF('RATS Entry Import'!F7="","",'RATS Entry Import'!F7)) -> Final | AO7: =IF($AJ7="","",IF('RATS Entry Import'!G7="","",'RATS Entry Import'!G7)) -> OnLineForm | AP7: =IF($AJ7="","",IF('RATS Entry Import'!J7="","",'RATS Entry Import'!J7))
A8: =IF($AJ8="","",IF(OR($G8="",$B8="",$D8=""),"MISSING DETAILS",IF(AND($E8<>"Junior",$E8<>"Senior"),"INVALID LEVEL",IF($AH8<>1,"UNMAPPED CHALLENGE","OK")))) -> OK | B8: =IF($AJ8="","",IF('RATS Entry Import'!B8="","",'RATS Entry Import'!B8)) -> Example Robot 07 | C8: =IF($AJ8="","",IF('RATS Entry Import'!E8="","",'RATS Entry Import'!E8)) -> Half Size Line Follower | D8: =IF($AJ8="","",IF('RATS Entry Import'!H8="","",'RATS Entry Import'!H8)) -> Example Contestant 07 | E8: =IF($AJ8="","",IF('RATS Entry Import'!I8="","",'RATS Entry Import'!I8)) -> Senior | F8: =IF($AJ8="","","") | G8: =IF($AJ8="","",IF('RATS Entry Import'!A8="","",'RATS Entry Import'!A8)) -> 10007 | H8: =IF($AJ8="","",IF($AK8="LF",1,0)) -> 0 | I8: =IF($AJ8="","",IF($AK8="HLF",1,0)) -> 1 | J8: =IF($AJ8="","",IF($AK8="DR",1,0)) -> 0 | K8: =IF($AJ8="","",IF($AK8="WF",1,0)) -> 0 | L8: =IF($AJ8="","",IF($AK8="HWF",1,0)) -> 0 | M8: =IF($AJ8="","",IF($AK8="MS",1,0)) -> 0 | N8: =IF($AJ8="","",IF($AK8="HMS",1,0)) -> 0 | O8: =IF($AJ8="","",IF($AK8="PUR",1,0)) -> 0 | Q8: =IF(AND($AJ8<>"",$E8="Junior",H8>0),H8,"") | R8: =IF(AND($AJ8<>"",$E8="Junior",I8>0),I8,"") | S8: =IF(AND($AJ8<>"",$E8="Junior",J8>0),J8,"") | T8: =IF(AND($AJ8<>"",$E8="Junior",K8>0),K8,"") | U8: =IF(AND($AJ8<>"",$E8="Junior",L8>0),L8,"") | V8: =IF(AND($AJ8<>"",$E8="Junior",M8>0),M8,"") | W8: =IF(AND($AJ8<>"",$E8="Junior",N8>0),N8,"") | X8: =IF(AND($AJ8<>"",$E8="Junior",O8>0),O8,"") | Y8: =IF(AND($AJ8<>"",$E8="Senior",H8>0),H8,"") | Z8: =IF(AND($AJ8<>"",$E8="Senior",I8>0),I8,"") -> 1 | AA8: =IF(AND($AJ8<>"",$E8="Senior",J8>0),J8,"") | AB8: =IF(AND($AJ8<>"",$E8="Senior",K8>0),K8,"") | AC8: =IF(AND($AJ8<>"",$E8="Senior",L8>0),L8,"") | AD8: =IF(AND($AJ8<>"",$E8="Senior",M8>0),M8,"") | AE8: =IF(AND($AJ8<>"",$E8="Senior",N8>0),N8,"") | AF8: =IF(AND($AJ8<>"",$E8="Senior",O8>0),O8,"") | AG8: =IF($AJ8="","",SUM(H8:O8)) -> 1 | AH8: =IF($AJ8="","",SUM(Q8:AF8)) -> 1 | AI8: =IF($AJ8="","",AG8-AH8) -> 0 | AJ8: =IF(COUNTA('RATS Entry Import'!A8:J8)=0,"",ROW()) -> 8 | AK8: =IF($AJ8="","",IFERROR(VLOOKUP($C8,'Event Mapping'!$A$2:$B$100,2,FALSE),"UNMAPPED")) -> HLF | AL8: =IF($AJ8="","",IF('RATS Entry Import'!D8="","",'RATS Entry Import'!D8)) -> Senior Line Follower | AM8: =IF($AJ8="","",IF('RATS Entry Import'!C8="","",'RATS Entry Import'!C8)) -> 9002 | AN8: =IF($AJ8="","",IF('RATS Entry Import'!F8="","",'RATS Entry Import'!F8)) -> Final | AO8: =IF($AJ8="","",IF('RATS Entry Import'!G8="","",'RATS Entry Import'!G8)) -> OnLineForm | AP8: =IF($AJ8="","",IF('RATS Entry Import'!J8="","",'RATS Entry Import'!J8))
A9: =IF($AJ9="","",IF(OR($G9="",$B9="",$D9=""),"MISSING DETAILS",IF(AND($E9<>"Junior",$E9<>"Senior"),"INVALID LEVEL",IF($AH9<>1,"UNMAPPED CHALLENGE","OK")))) -> OK | B9: =IF($AJ9="","",IF('RATS Entry Import'!B9="","",'RATS Entry Import'!B9)) -> Example Robot 08 | C9: =IF($AJ9="","",IF('RATS Entry Import'!E9="","",'RATS Entry Import'!E9)) -> Half Size Line Follower | D9: =IF($AJ9="","",IF('RATS Entry Import'!H9="","",'RATS Entry Import'!H9)) -> Example Contestant 07 | E9: =IF($AJ9="","",IF('RATS Entry Import'!I9="","",'RATS Entry Import'!I9)) -> Senior | F9: =IF($AJ9="","","") | G9: =IF($AJ9="","",IF('RATS Entry Import'!A9="","",'RATS Entry Import'!A9)) -> 10008 | H9: =IF($AJ9="","",IF($AK9="LF",1,0)) -> 0 | I9: =IF($AJ9="","",IF($AK9="HLF",1,0)) -> 1 | J9: =IF($AJ9="","",IF($AK9="DR",1,0)) -> 0 | K9: =IF($AJ9="","",IF($AK9="WF",1,0)) -> 0 | L9: =IF($AJ9="","",IF($AK9="HWF",1,0)) -> 0 | M9: =IF($AJ9="","",IF($AK9="MS",1,0)) -> 0 | N9: =IF($AJ9="","",IF($AK9="HMS",1,0)) -> 0 | O9: =IF($AJ9="","",IF($AK9="PUR",1,0)) -> 0 | Q9: =IF(AND($AJ9<>"",$E9="Junior",H9>0),H9,"") | R9: =IF(AND($AJ9<>"",$E9="Junior",I9>0),I9,"") | S9: =IF(AND($AJ9<>"",$E9="Junior",J9>0),J9,"") | T9: =IF(AND($AJ9<>"",$E9="Junior",K9>0),K9,"") | U9: =IF(AND($AJ9<>"",$E9="Junior",L9>0),L9,"") | V9: =IF(AND($AJ9<>"",$E9="Junior",M9>0),M9,"") | W9: =IF(AND($AJ9<>"",$E9="Junior",N9>0),N9,"") | X9: =IF(AND($AJ9<>"",$E9="Junior",O9>0),O9,"") | Y9: =IF(AND($AJ9<>"",$E9="Senior",H9>0),H9,"") | Z9: =IF(AND($AJ9<>"",$E9="Senior",I9>0),I9,"") -> 1 | AA9: =IF(AND($AJ9<>"",$E9="Senior",J9>0),J9,"") | AB9: =IF(AND($AJ9<>"",$E9="Senior",K9>0),K9,"") | AC9: =IF(AND($AJ9<>"",$E9="Senior",L9>0),L9,"") | AD9: =IF(AND($AJ9<>"",$E9="Senior",M9>0),M9,"") | AE9: =IF(AND($AJ9<>"",$E9="Senior",N9>0),N9,"") | AF9: =IF(AND($AJ9<>"",$E9="Senior",O9>0),O9,"") | AG9: =IF($AJ9="","",SUM(H9:O9)) -> 1 | AH9: =IF($AJ9="","",SUM(Q9:AF9)) -> 1 | AI9: =IF($AJ9="","",AG9-AH9) -> 0 | AJ9: =IF(COUNTA('RATS Entry Import'!A9:J9)=0,"",ROW()) -> 9 | AK9: =IF($AJ9="","",IFERROR(VLOOKUP($C9,'Event Mapping'!$A$2:$B$100,2,FALSE),"UNMAPPED")) -> HLF | AL9: =IF($AJ9="","",IF('RATS Entry Import'!D9="","",'RATS Entry Import'!D9)) -> Senior Line Follower | AM9: =IF($AJ9="","",IF('RATS Entry Import'!C9="","",'RATS Entry Import'!C9)) -> 9002 | AN9: =IF($AJ9="","",IF('RATS Entry Import'!F9="","",'RATS Entry Import'!F9)) -> Final | AO9: =IF($AJ9="","",IF('RATS Entry Import'!G9="","",'RATS Entry Import'!G9)) -> OnLineForm | AP9: =IF($AJ9="","",IF('RATS Entry Import'!J9="","",'RATS Entry Import'!J9))
A10: =IF($AJ10="","",IF(OR($G10="",$B10="",$D10=""),"MISSING DETAILS",IF(AND($E10<>"Junior",$E10<>"Senior"),"INVALID LEVEL",IF($AH10<>1,"UNMAPPED CHALLENGE","OK")))) -> OK | B10: =IF($AJ10="","",IF('RATS Entry Import'!B10="","",'RATS Entry Import'!B10)) -> Example Robot 09 | C10: =IF($AJ10="","",IF('RATS Entry Import'!E10="","",'RATS Entry Import'!E10)) -> Half Size Line Follower | D10: =IF($AJ10="","",IF('RATS Entry Import'!H10="","",'RATS Entry Import'!H10)) -> Example Contestant 08 | E10: =IF($AJ10="","",IF('RATS Entry Import'!I10="","",'RATS Entry Import'!I10)) -> Senior | F10: =IF($AJ10="","","") | G10: =IF($AJ10="","",IF('RATS Entry Import'!A10="","",'RATS Entry Import'!A10)) -> 10009 | H10: =IF($AJ10="","",IF($AK10="LF",1,0)) -> 0 | I10: =IF($AJ10="","",IF($AK10="HLF",1,0)) -> 1 | J10: =IF($AJ10="","",IF($AK10="DR",1,0)) -> 0 | K10: =IF($AJ10="","",IF($AK10="WF",1,0)) -> 0 | L10: =IF($AJ10="","",IF($AK10="HWF",1,0)) -> 0 | M10: =IF($AJ10="","",IF($AK10="MS",1,0)) -> 0 | N10: =IF($AJ10="","",IF($AK10="HMS",1,0)) -> 0 | O10: =IF($AJ10="","",IF($AK10="PUR",1,0)) -> 0 | Q10: =IF(AND($AJ10<>"",$E10="Junior",H10>0),H10,"") | R10: =IF(AND($AJ10<>"",$E10="Junior",I10>0),I10,"") | S10: =IF(AND($AJ10<>"",$E10="Junior",J10>0),J10,"") | T10: =IF(AND($AJ10<>"",$E10="Junior",K10>0),K10,"") | U10: =IF(AND($AJ10<>"",$E10="Junior",L10>0),L10,"") | V10: =IF(AND($AJ10<>"",$E10="Junior",M10>0),M10,"") | W10: =IF(AND($AJ10<>"",$E10="Junior",N10>0),N10,"") | X10: =IF(AND($AJ10<>"",$E10="Junior",O10>0),O10,"") | Y10: =IF(AND($AJ10<>"",$E10="Senior",H10>0),H10,"") | Z10: =IF(AND($AJ10<>"",$E10="Senior",I10>0),I10,"") -> 1 | AA10: =IF(AND($AJ10<>"",$E10="Senior",J10>0),J10,"") | AB10: =IF(AND($AJ10<>"",$E10="Senior",K10>0),K10,"") | AC10: =IF(AND($AJ10<>"",$E10="Senior",L10>0),L10,"") | AD10: =IF(AND($AJ10<>"",$E10="Senior",M10>0),M10,"") | AE10: =IF(AND($AJ10<>"",$E10="Senior",N10>0),N10,"") | AF10: =IF(AND($AJ10<>"",$E10="Senior",O10>0),O10,"") | AG10: =IF($AJ10="","",SUM(H10:O10)) -> 1 | AH10: =IF($AJ10="","",SUM(Q10:AF10)) -> 1 | AI10: =IF($AJ10="","",AG10-AH10) -> 0 | AJ10: =IF(COUNTA('RATS Entry Import'!A10:J10)=0,"",ROW()) -> 10 | AK10: =IF($AJ10="","",IFERROR(VLOOKUP($C10,'Event Mapping'!$A$2:$B$100,2,FALSE),"UNMAPPED")) -> HLF | AL10: =IF($AJ10="","",IF('RATS Entry Import'!D10="","",'RATS Entry Import'!D10)) -> Senior Line Follower | AM10: =IF($AJ10="","",IF('RATS Entry Import'!C10="","",'RATS Entry Import'!C10)) -> 9002 | AN10: =IF($AJ10="","",IF('RATS Entry Import'!F10="","",'RATS Entry Import'!F10)) -> Final | AO10: =IF($AJ10="","",IF('RATS Entry Import'!G10="","",'RATS Entry Import'!G10)) -> OnLineForm | AP10: =IF($AJ10="","",IF('RATS Entry Import'!J10="","",'RATS Entry Import'!J10))
A11: =IF($AJ11="","",IF(OR($G11="",$B11="",$D11=""),"MISSING DETAILS",IF(AND($E11<>"Junior",$E11<>"Senior"),"INVALID LEVEL",IF($AH11<>1,"UNMAPPED CHALLENGE","OK")))) -> OK | B11: =IF($AJ11="","",IF('RATS Entry Import'!B11="","",'RATS Entry Import'!B11)) -> Example Robot 10 | C11: =IF($AJ11="","",IF('RATS Entry Import'!E11="","",'RATS Entry Import'!E11)) -> Half Size Line Follower | D11: =IF($AJ11="","",IF('RATS Entry Import'!H11="","",'RATS Entry Import'!H11)) -> Example Contestant 09 | E11: =IF($AJ11="","",IF('RATS Entry Import'!I11="","",'RATS Entry Import'!I11)) -> Senior | F11: =IF($AJ11="","","") | G11: =IF($AJ11="","",IF('RATS Entry Import'!A11="","",'RATS Entry Import'!A11)) -> 10010 | H11: =IF($AJ11="","",IF($AK11="LF",1,0)) -> 0 | I11: =IF($AJ11="","",IF($AK11="HLF",1,0)) -> 1 | J11: =IF($AJ11="","",IF($AK11="DR",1,0)) -> 0 | K11: =IF($AJ11="","",IF($AK11="WF",1,0)) -> 0 | L11: =IF($AJ11="","",IF($AK11="HWF",1,0)) -> 0 | M11: =IF($AJ11="","",IF($AK11="MS",1,0)) -> 0 | N11: =IF($AJ11="","",IF($AK11="HMS",1,0)) -> 0 | O11: =IF($AJ11="","",IF($AK11="PUR",1,0)) -> 0 | Q11: =IF(AND($AJ11<>"",$E11="Junior",H11>0),H11,"") | R11: =IF(AND($AJ11<>"",$E11="Junior",I11>0),I11,"") | S11: =IF(AND($AJ11<>"",$E11="Junior",J11>0),J11,"") | T11: =IF(AND($AJ11<>"",$E11="Junior",K11>0),K11,"") | U11: =IF(AND($AJ11<>"",$E11="Junior",L11>0),L11,"") | V11: =IF(AND($AJ11<>"",$E11="Junior",M11>0),M11,"") | W11: =IF(AND($AJ11<>"",$E11="Junior",N11>0),N11,"") | X11: =IF(AND($AJ11<>"",$E11="Junior",O11>0),O11,"") | Y11: =IF(AND($AJ11<>"",$E11="Senior",H11>0),H11,"") | Z11: =IF(AND($AJ11<>"",$E11="Senior",I11>0),I11,"") -> 1 | AA11: =IF(AND($AJ11<>"",$E11="Senior",J11>0),J11,"") | AB11: =IF(AND($AJ11<>"",$E11="Senior",K11>0),K11,"") | AC11: =IF(AND($AJ11<>"",$E11="Senior",L11>0),L11,"") | AD11: =IF(AND($AJ11<>"",$E11="Senior",M11>0),M11,"") | AE11: =IF(AND($AJ11<>"",$E11="Senior",N11>0),N11,"") | AF11: =IF(AND($AJ11<>"",$E11="Senior",O11>0),O11,"") | AG11: =IF($AJ11="","",SUM(H11:O11)) -> 1 | AH11: =IF($AJ11="","",SUM(Q11:AF11)) -> 1 | AI11: =IF($AJ11="","",AG11-AH11) -> 0 | AJ11: =IF(COUNTA('RATS Entry Import'!A11:J11)=0,"",ROW()) -> 11 | AK11: =IF($AJ11="","",IFERROR(VLOOKUP($C11,'Event Mapping'!$A$2:$B$100,2,FALSE),"UNMAPPED")) -> HLF | AL11: =IF($AJ11="","",IF('RATS Entry Import'!D11="","",'RATS Entry Import'!D11)) -> Senior Line Follower | AM11: =IF($AJ11="","",IF('RATS Entry Import'!C11="","",'RATS Entry Import'!C11)) -> 9002 | AN11: =IF($AJ11="","",IF('RATS Entry Import'!F11="","",'RATS Entry Import'!F11)) -> Final | AO11: =IF($AJ11="","",IF('RATS Entry Import'!G11="","",'RATS Entry Import'!G11)) -> OnLineForm | AP11: =IF($AJ11="","",IF('RATS Entry Import'!J11="","",'RATS Entry Import'!J11))
A12: =IF($AJ12="","",IF(OR($G12="",$B12="",$D12=""),"MISSING DETAILS",IF(AND($E12<>"Junior",$E12<>"Senior"),"INVALID LEVEL",IF($AH12<>1,"UNMAPPED CHALLENGE","OK")))) -> OK | B12: =IF($AJ12="","",IF('RATS Entry Import'!B12="","",'RATS Entry Import'!B12)) -> Example Robot 11 | C12: =IF($AJ12="","",IF('RATS Entry Import'!E12="","",'RATS Entry Import'!E12)) -> Half Size Line Follower | D12: =IF($AJ12="","",IF('RATS Entry Import'!H12="","",'RATS Entry Import'!H12)) -> Example Contestant 09 | E12: =IF($AJ12="","",IF('RATS Entry Import'!I12="","",'RATS Entry Import'!I12)) -> Senior | F12: =IF($AJ12="","","") | G12: =IF($AJ12="","",IF('RATS Entry Import'!A12="","",'RATS Entry Import'!A12)) -> 10011 | H12: =IF($AJ12="","",IF($AK12="LF",1,0)) -> 0 | I12: =IF($AJ12="","",IF($AK12="HLF",1,0)) -> 1 | J12: =IF($AJ12="","",IF($AK12="DR",1,0)) -> 0 | K12: =IF($AJ12="","",IF($AK12="WF",1,0)) -> 0 | L12: =IF($AJ12="","",IF($AK12="HWF",1,0)) -> 0 | M12: =IF($AJ12="","",IF($AK12="MS",1,0)) -> 0 | N12: =IF($AJ12="","",IF($AK12="HMS",1,0)) -> 0 | O12: =IF($AJ12="","",IF($AK12="PUR",1,0)) -> 0 | Q12: =IF(AND($AJ12<>"",$E12="Junior",H12>0),H12,"") | R12: =IF(AND($AJ12<>"",$E12="Junior",I12>0),I12,"") | S12: =IF(AND($AJ12<>"",$E12="Junior",J12>0),J12,"") | T12: =IF(AND($AJ12<>"",$E12="Junior",K12>0),K12,"") | U12: =IF(AND($AJ12<>"",$E12="Junior",L12>0),L12,"") | V12: =IF(AND($AJ12<>"",$E12="Junior",M12>0),M12,"") | W12: =IF(AND($AJ12<>"",$E12="Junior",N12>0),N12,"") | X12: =IF(AND($AJ12<>"",$E12="Junior",O12>0),O12,"") | Y12: =IF(AND($AJ12<>"",$E12="Senior",H12>0),H12,"") | Z12: =IF(AND($AJ12<>"",$E12="Senior",I12>0),I12,"") -> 1 | AA12: =IF(AND($AJ12<>"",$E12="Senior",J12>0),J12,"") | AB12: =IF(AND($AJ12<>"",$E12="Senior",K12>0),K12,"") | AC12: =IF(AND($AJ12<>"",$E12="Senior",L12>0),L12,"") | AD12: =IF(AND($AJ12<>"",$E12="Senior",M12>0),M12,"") | AE12: =IF(AND($AJ12<>"",$E12="Senior",N12>0),N12,"") | AF12: =IF(AND($AJ12<>"",$E12="Senior",O12>0),O12,"") | AG12: =IF($AJ12="","",SUM(H12:O12)) -> 1 | AH12: =IF($AJ12="","",SUM(Q12:AF12)) -> 1 | AI12: =IF($AJ12="","",AG12-AH12) -> 0 | AJ12: =IF(COUNTA('RATS Entry Import'!A12:J12)=0,"",ROW()) -> 12 | AK12: =IF($AJ12="","",IFERROR(VLOOKUP($C12,'Event Mapping'!$A$2:$B$100,2,FALSE),"UNMAPPED")) -> HLF | AL12: =IF($AJ12="","",IF('RATS Entry Import'!D12="","",'RATS Entry Import'!D12)) -> Senior Line Follower | AM12: =IF($AJ12="","",IF('RATS Entry Import'!C12="","",'RATS Entry Import'!C12)) -> 9002 | AN12: =IF($AJ12="","",IF('RATS Entry Import'!F12="","",'RATS Entry Import'!F12)) -> Final | AO12: =IF($AJ12="","",IF('RATS Entry Import'!G12="","",'RATS Entry Import'!G12)) -> OnLineForm | AP12: =IF($AJ12="","",IF('RATS Entry Import'!J12="","",'RATS Entry Import'!J12))
A13: =IF($AJ13="","",IF(OR($G13="",$B13="",$D13=""),"MISSING DETAILS",IF(AND($E13<>"Junior",$E13<>"Senior"),"INVALID LEVEL",IF($AH13<>1,"UNMAPPED CHALLENGE","OK")))) -> OK | B13: =IF($AJ13="","",IF('RATS Entry Import'!B13="","",'RATS Entry Import'!B13)) -> Example Robot 12 | C13: =IF($AJ13="","",IF('RATS Entry Import'!E13="","",'RATS Entry Import'!E13)) -> Half Size Line Follower | D13: =IF($AJ13="","",IF('RATS Entry Import'!H13="","",'RATS Entry Import'!H13)) -> Example Contestant 05 | E13: =IF($AJ13="","",IF('RATS Entry Import'!I13="","",'RATS Entry Import'!I13)) -> Senior | F13: =IF($AJ13="","","") | G13: =IF($AJ13="","",IF('RATS Entry Import'!A13="","",'RATS Entry Import'!A13)) -> 10012 | H13: =IF($AJ13="","",IF($AK13="LF",1,0)) -> 0 | I13: =IF($AJ13="","",IF($AK13="HLF",1,0)) -> 1 | J13: =IF($AJ13="","",IF($AK13="DR",1,0)) -> 0 | K13: =IF($AJ13="","",IF($AK13="WF",1,0)) -> 0 | L13: =IF($AJ13="","",IF($AK13="HWF",1,0)) -> 0 | M13: =IF($AJ13="","",IF($AK13="MS",1,0)) -> 0 | N13: =IF($AJ13="","",IF($AK13="HMS",1,0)) -> 0 | O13: =IF($AJ13="","",IF($AK13="PUR",1,0)) -> 0 | Q13: =IF(AND($AJ13<>"",$E13="Junior",H13>0),H13,"") | R13: =IF(AND($AJ13<>"",$E13="Junior",I13>0),I13,"") | S13: =IF(AND($AJ13<>"",$E13="Junior",J13>0),J13,"") | T13: =IF(AND($AJ13<>"",$E13="Junior",K13>0),K13,"") | U13: =IF(AND($AJ13<>"",$E13="Junior",L13>0),L13,"") | V13: =IF(AND($AJ13<>"",$E13="Junior",M13>0),M13,"") | W13: =IF(AND($AJ13<>"",$E13="Junior",N13>0),N13,"") | X13: =IF(AND($AJ13<>"",$E13="Junior",O13>0),O13,"") | Y13: =IF(AND($AJ13<>"",$E13="Senior",H13>0),H13,"") | Z13: =IF(AND($AJ13<>"",$E13="Senior",I13>0),I13,"") -> 1 | AA13: =IF(AND($AJ13<>"",$E13="Senior",J13>0),J13,"") | AB13: =IF(AND($AJ13<>"",$E13="Senior",K13>0),K13,"") | AC13: =IF(AND($AJ13<>"",$E13="Senior",L13>0),L13,"") | AD13: =IF(AND($AJ13<>"",$E13="Senior",M13>0),M13,"") | AE13: =IF(AND($AJ13<>"",$E13="Senior",N13>0),N13,"") | AF13: =IF(AND($AJ13<>"",$E13="Senior",O13>0),O13,"") | AG13: =IF($AJ13="","",SUM(H13:O13)) -> 1 | AH13: =IF($AJ13="","",SUM(Q13:AF13)) -> 1 | AI13: =IF($AJ13="","",AG13-AH13) -> 0 | AJ13: =IF(COUNTA('RATS Entry Import'!A13:J13)=0,"",ROW()) -> 13 | AK13: =IF($AJ13="","",IFERROR(VLOOKUP($C13,'Event Mapping'!$A$2:$B$100,2,FALSE),"UNMAPPED")) -> HLF | AL13: =IF($AJ13="","",IF('RATS Entry Import'!D13="","",'RATS Entry Import'!D13)) -> Senior Line Follower | AM13: =IF($AJ13="","",IF('RATS Entry Import'!C13="","",'RATS Entry Import'!C13)) -> 9002 | AN13: =IF($AJ13="","",IF('RATS Entry Import'!F13="","",'RATS Entry Import'!F13)) -> Final | AO13: =IF($AJ13="","",IF('RATS Entry Import'!G13="","",'RATS Entry Import'!G13)) -> OnLineForm | AP13: =IF($AJ13="","",IF('RATS Entry Import'!J13="","",'RATS Entry Import'!J13))
... A1001: =IF($AJ1001="","",IF(OR($G1001="",$B1001="",$D1001=""),"MISSING DETAILS",IF(AND($E1001<>"Junior",$E1001<>"Senior"),"INVALID LEVEL",IF($AH1001<>1,"UNMAPPED CHALLENGE","OK")))) | B1001: =IF($AJ1001="","",IF('RATS Entry Import'!B1001="","",'RATS Entry Import'!B1001)) | C1001: =IF($AJ1001="","",IF('RATS Entry Import'!E1001="","",'RATS Entry Import'!E1001)) | D1001: =IF($AJ1001="","",IF('RATS Entry Import'!H1001="","",'RATS Entry Import'!H1001)) | E1001: =IF($AJ1001="","",IF('RATS Entry Import'!I1001="","",'RATS Entry Import'!I1001)) | F1001: =IF($AJ1001="","","") | G1001: =IF($AJ1001="","",IF('RATS Entry Import'!A1001="","",'RATS Entry Import'!A1001)) | H1001: =IF($AJ1001="","",IF($AK1001="LF",1,0)) | I1001: =IF($AJ1001="","",IF($AK1001="HLF",1,0)) | J1001: =IF($AJ1001="","",IF($AK1001="DR",1,0)) | K1001: =IF($AJ1001="","",IF($AK1001="WF",1,0)) | L1001: =IF($AJ1001="","",IF($AK1001="HWF",1,0)) | M1001: =IF($AJ1001="","",IF($AK1001="MS",1,0)) | N1001: =IF($AJ1001="","",IF($AK1001="HMS",1,0)) | O1001: =IF($AJ1001="","",IF($AK1001="PUR",1,0)) | Q1001: =IF(AND($AJ1001<>"",$E1001="Junior",H1001>0),H1001,"") | R1001: =IF(AND($AJ1001<>"",$E1001="Junior",I1001>0),I1001,"") | S1001: =IF(AND($AJ1001<>"",$E1001="Junior",J1001>0),J1001,"") | T1001: =IF(AND($AJ1001<>"",$E1001="Junior",K1001>0),K1001,"") | U1001: =IF(AND($AJ1001<>"",$E1001="Junior",L1001>0),L1001,"") | V1001: =IF(AND($AJ1001<>"",$E1001="Junior",M1001>0),M1001,"") | W1001: =IF(AND($AJ1001<>"",$E1001="Junior",N1001>0),N1001,"") | X1001: =IF(AND($AJ1001<>"",$E1001="Junior",O1001>0),O1001,"") | Y1001: =IF(AND($AJ1001<>"",$E1001="Senior",H1001>0),H1001,"") | Z1001: =IF(AND($AJ1001<>"",$E1001="Senior",I1001>0),I1001,"") | AA1001: =IF(AND($AJ1001<>"",$E1001="Senior",J1001>0),J1001,"") | AB1001: =IF(AND($AJ1001<>"",$E1001="Senior",K1001>0),K1001,"") | AC1001: =IF(AND($AJ1001<>"",$E1001="Senior",L1001>0),L1001,"") | AD1001: =IF(AND($AJ1001<>"",$E1001="Senior",M1001>0),M1001,"") | AE1001: =IF(AND($AJ1001<>"",$E1001="Senior",N1001>0),N1001,"") | AF1001: =IF(AND($AJ1001<>"",$E1001="Senior",O1001>0),O1001,"") | AG1001: =IF($AJ1001="","",SUM(H1001:O1001)) | AH1001: =IF($AJ1001="","",SUM(Q1001:AF1001)) | AI1001: =IF($AJ1001="","",AG1001-AH1001) | AJ1001: =IF(COUNTA('RATS Entry Import'!A1001:J1001)=0,"",ROW()) | AK1001: =IF($AJ1001="","",IFERROR(VLOOKUP($C1001,'Event Mapping'!$A$2:$B$100,2,FALSE),"UNMAPPED")) | AL1001: =IF($AJ1001="","",IF('RATS Entry Import'!D1001="","",'RATS Entry Import'!D1001)) | AM1001: =IF($AJ1001="","",IF('RATS Entry Import'!C1001="","",'RATS Entry Import'!C1001)) | AN1001: =IF($AJ1001="","",IF('RATS Entry Import'!F1001="","",'RATS Entry Import'!F1001)) | AO1001: =IF($AJ1001="","",IF('RATS Entry Import'!G1001="","",'RATS Entry Import'!G1001)) | AP1001: =IF($AJ1001="","",IF('RATS Entry Import'!J1001="","",'RATS Entry Import'!J1001))
A1004: Classic formula version of RobotLookup without ZZZ placeholders. Uses scalar helper formulas only and supports up to 200 responses.

Sheet Junior Half Size Line Follower
A1: Junior Half Size Line Follower
A4: Robot Name | B4: Builder Name | C4: Run 1 | D4: Touch | E4: Run 2 | F4: Touch2 | G4: Run 3 | H4: Touch3 | I4: Best Run | J4: Position | K4: Notes | X4: Source Row | Y4: Robot Name | Z4: Sort Rank | AA4: Match Pos | AB4: Sorted Source Row
A5: =IF($AB5="","",INDEX('RobotLookup Clean'!$B:$B,$AB5)) -> Example Robot 01 | B5: =IF($AB5="","",INDEX('RobotLookup Clean'!$D:$D,$AB5)) -> Example Contestant 01 | X5: =IF(AND(INDEX('RobotLookup Clean'!$E:$E,ROW()-3)="Junior",INDEX('RobotLookup Clean'!$R:$R,ROW()-3)=1),ROW()-3,"") -> 2 | Y5: =IF($X5="","",INDEX('RobotLookup Clean'!$B:$B,$X5)) -> Example Robot 01 | Z5: =IF($X5="","",SUMPRODUCT(($X$5:$X$1004<>"")*($Y$5:$Y$1004<$Y5))+SUMPRODUCT(($X$5:$X$1004<>"")*($Y$5:$Y$1004=$Y5)*($X$5:$X$1004<$X5))+1) -> 1 | AA5: =IFERROR(MATCH(ROWS($AA$5:AA5),$Z$5:$Z$1004,0),"") -> 1 | AB5: =IF($AA5="","",INDEX($X$5:$X$1004,$AA5)) -> 2
A6: =IF($AB6="","",INDEX('RobotLookup Clean'!$B:$B,$AB6)) -> Example Robot 02 | B6: =IF($AB6="","",INDEX('RobotLookup Clean'!$D:$D,$AB6)) -> Example Contestant 02 | X6: =IF(AND(INDEX('RobotLookup Clean'!$E:$E,ROW()-3)="Junior",INDEX('RobotLookup Clean'!$R:$R,ROW()-3)=1),ROW()-3,"") -> 3 | Y6: =IF($X6="","",INDEX('RobotLookup Clean'!$B:$B,$X6)) -> Example Robot 02 | Z6: =IF($X6="","",SUMPRODUCT(($X$5:$X$1004<>"")*($Y$5:$Y$1004<$Y6))+SUMPRODUCT(($X$5:$X$1004<>"")*($Y$5:$Y$1004=$Y6)*($X$5:$X$1004<$X6))+1) -> 2 | AA6: =IFERROR(MATCH(ROWS($AA$5:AA6),$Z$5:$Z$1004,0),"") -> 2 | AB6: =IF($AA6="","",INDEX($X$5:$X$1004,$AA6)) -> 3
A7: =IF($AB7="","",INDEX('RobotLookup Clean'!$B:$B,$AB7)) -> Example Robot 03 | B7: =IF($AB7="","",INDEX('RobotLookup Clean'!$D:$D,$AB7)) -> Example Contestant 03 | X7: =IF(AND(INDEX('RobotLookup Clean'!$E:$E,ROW()-3)="Junior",INDEX('RobotLookup Clean'!$R:$R,ROW()-3)=1),ROW()-3,"") -> 4 | Y7: =IF($X7="","",INDEX('RobotLookup Clean'!$B:$B,$X7)) -> Example Robot 03 | Z7: =IF($X7="","",SUMPRODUCT(($X$5:$X$1004<>"")*($Y$5:$Y$1004<$Y7))+SUMPRODUCT(($X$5:$X$1004<>"")*($Y$5:$Y$1004=$Y7)*($X$5:$X$1004<$X7))+1) -> 3 | AA7: =IFERROR(MATCH(ROWS($AA$5:AA7),$Z$5:$Z$1004,0),"") -> 3 | AB7: =IF($AA7="","",INDEX($X$5:$X$1004,$AA7)) -> 4
A8: =IF($AB8="","",INDEX('RobotLookup Clean'!$B:$B,$AB8)) | B8: =IF($AB8="","",INDEX('RobotLookup Clean'!$D:$D,$AB8)) | X8: =IF(AND(INDEX('RobotLookup Clean'!$E:$E,ROW()-3)="Junior",INDEX('RobotLookup Clean'!$R:$R,ROW()-3)=1),ROW()-3,"") | Y8: =IF($X8="","",INDEX('RobotLookup Clean'!$B:$B,$X8)) | Z8: =IF($X8="","",SUMPRODUCT(($X$5:$X$1004<>"")*($Y$5:$Y$1004<$Y8))+SUMPRODUCT(($X$5:$X$1004<>"")*($Y$5:$Y$1004=$Y8)*($X$5:$X$1004<$X8))+1) | AA8: =IFERROR(MATCH(ROWS($AA$5:AA8),$Z$5:$Z$1004,0),"") | AB8: =IF($AA8="","",INDEX($X$5:$X$1004,$AA8))
A9: =IF($AB9="","",INDEX('RobotLookup Clean'!$B:$B,$AB9)) | B9: =IF($AB9="","",INDEX('RobotLookup Clean'!$D:$D,$AB9)) | X9: =IF(AND(INDEX('RobotLookup Clean'!$E:$E,ROW()-3)="Junior",INDEX('RobotLookup Clean'!$R:$R,ROW()-3)=1),ROW()-3,"") | Y9: =IF($X9="","",INDEX('RobotLookup Clean'!$B:$B,$X9)) | Z9: =IF($X9="","",SUMPRODUCT(($X$5:$X$1004<>"")*($Y$5:$Y$1004<$Y9))+SUMPRODUCT(($X$5:$X$1004<>"")*($Y$5:$Y$1004=$Y9)*($X$5:$X$1004<$X9))+1) | AA9: =IFERROR(MATCH(ROWS($AA$5:AA9),$Z$5:$Z$1004,0),"") | AB9: =IF($AA9="","",INDEX($X$5:$X$1004,$AA9))
A10: =IF($AB10="","",INDEX('RobotLookup Clean'!$B:$B,$AB10)) | B10: =IF($AB10="","",INDEX('RobotLookup Clean'!$D:$D,$AB10)) | X10: =IF(AND(INDEX('RobotLookup Clean'!$E:$E,ROW()-3)="Junior",INDEX('RobotLookup Clean'!$R:$R,ROW()-3)=1),ROW()-3,"") | Y10: =IF($X10="","",INDEX('RobotLookup Clean'!$B:$B,$X10)) | Z10: =IF($X10="","",SUMPRODUCT(($X$5:$X$1004<>"")*($Y$5:$Y$1004<$Y10))+SUMPRODUCT(($X$5:$X$1004<>"")*($Y$5:$Y$1004=$Y10)*($X$5:$X$1004<$X10))+1) | AA10: =IFERROR(MATCH(ROWS($AA$5:AA10),$Z$5:$Z$1004,0),"") | AB10: =IF($AA10="","",INDEX($X$5:$X$1004,$AA10))
A11: =IF($AB11="","",INDEX('RobotLookup Clean'!$B:$B,$AB11)) | B11: =IF($AB11="","",INDEX('RobotLookup Clean'!$D:$D,$AB11)) | X11: =IF(AND(INDEX('RobotLookup Clean'!$E:$E,ROW()-3)="Junior",INDEX('RobotLookup Clean'!$R:$R,ROW()-3)=1),ROW()-3,"") | Y11: =IF($X11="","",INDEX('RobotLookup Clean'!$B:$B,$X11)) | Z11: =IF($X11="","",SUMPRODUCT(($X$5:$X$1004<>"")*($Y$5:$Y$1004<$Y11))+SUMPRODUCT(($X$5:$X$1004<>"")*($Y$5:$Y$1004=$Y11)*($X$5:$X$1004<$X11))+1) | AA11: =IFERROR(MATCH(ROWS($AA$5:AA11),$Z$5:$Z$1004,0),"") | AB11: =IF($AA11="","",INDEX($X$5:$X$1004,$AA11))
A12: =IF($AB12="","",INDEX('RobotLookup Clean'!$B:$B,$AB12)) | B12: =IF($AB12="","",INDEX('RobotLookup Clean'!$D:$D,$AB12)) | X12: =IF(AND(INDEX('RobotLookup Clean'!$E:$E,ROW()-3)="Junior",INDEX('RobotLookup Clean'!$R:$R,ROW()-3)=1),ROW()-3,"") | Y12: =IF($X12="","",INDEX('RobotLookup Clean'!$B:$B,$X12)) | Z12: =IF($X12="","",SUMPRODUCT(($X$5:$X$1004<>"")*($Y$5:$Y$1004<$Y12))+SUMPRODUCT(($X$5:$X$1004<>"")*($Y$5:$Y$1004=$Y12)*($X$5:$X$1004<$X12))+1) | AA12: =IFERROR(MATCH(ROWS($AA$5:AA12),$Z$5:$Z$1004,0),"") | AB12: =IF($AA12="","",INDEX($X$5:$X$1004,$AA12))
A13: =IF($AB13="","",INDEX('RobotLookup Clean'!$B:$B,$AB13)) | B13: =IF($AB13="","",INDEX('RobotLookup Clean'!$D:$D,$AB13)) | X13: =IF(AND(INDEX('RobotLookup Clean'!$E:$E,ROW()-3)="Junior",INDEX('RobotLookup Clean'!$R:$R,ROW()-3)=1),ROW()-3,"") | Y13: =IF($X13="","",INDEX('RobotLookup Clean'!$B:$B,$X13)) | Z13: =IF($X13="","",SUMPRODUCT(($X$5:$X$1004<>"")*($Y$5:$Y$1004<$Y13))+SUMPRODUCT(($X$5:$X$1004<>"")*($Y$5:$Y$1004=$Y13)*($X$5:$X$1004<$X13))+1) | AA13: =IFERROR(MATCH(ROWS($AA$5:AA13),$Z$5:$Z$1004,0),"") | AB13: =IF($AA13="","",INDEX($X$5:$X$1004,$AA13))
A14: =IF($AB14="","",INDEX('RobotLookup Clean'!$B:$B,$AB14)) | B14: =IF($AB14="","",INDEX('RobotLookup Clean'!$D:$D,$AB14)) | X14: =IF(AND(INDEX('RobotLookup Clean'!$E:$E,ROW()-3)="Junior",INDEX('RobotLookup Clean'!$R:$R,ROW()-3)=1),ROW()-3,"") | Y14: =IF($X14="","",INDEX('RobotLookup Clean'!$B:$B,$X14)) | Z14: =IF($X14="","",SUMPRODUCT(($X$5:$X$1004<>"")*($Y$5:$Y$1004<$Y14))+SUMPRODUCT(($X$5:$X$1004<>"")*($Y$5:$Y$1004=$Y14)*($X$5:$X$1004<$X14))+1) | AA14: =IFERROR(MATCH(ROWS($AA$5:AA14),$Z$5:$Z$1004,0),"") | AB14: =IF($AA14="","",INDEX($X$5:$X$1004,$AA14))
A15: =IF($AB15="","",INDEX('RobotLookup Clean'!$B:$B,$AB15)) | B15: =IF($AB15="","",INDEX('RobotLookup Clean'!$D:$D,$AB15)) | X15: =IF(AND(INDEX('RobotLookup Clean'!$E:$E,ROW()-3)="Junior",INDEX('RobotLookup Clean'!$R:$R,ROW()-3)=1),ROW()-3,"") | Y15: =IF($X15="","",INDEX('RobotLookup Clean'!$B:$B,$X15)) | Z15: =IF($X15="","",SUMPRODUCT(($X$5:$X$1004<>"")*($Y$5:$Y$1004<$Y15))+SUMPRODUCT(($X$5:$X$1004<>"")*($Y$5:$Y$1004=$Y15)*($X$5:$X$1004<$X15))+1) | AA15: =IFERROR(MATCH(ROWS($AA$5:AA15),$Z$5:$Z$1004,0),"") | AB15: =IF($AA15="","",INDEX($X$5:$X$1004,$AA15))
A16: =IF($AB16="","",INDEX('RobotLookup Clean'!$B:$B,$AB16)) | B16: =IF($AB16="","",INDEX('RobotLookup Clean'!$D:$D,$AB16)) | X16: =IF(AND(INDEX('RobotLookup Clean'!$E:$E,ROW()-3)="Junior",INDEX('RobotLookup Clean'!$R:$R,ROW()-3)=1),ROW()-3,"") | Y16: =IF($X16="","",INDEX('RobotLookup Clean'!$B:$B,$X16)) | Z16: =IF($X16="","",SUMPRODUCT(($X$5:$X$1004<>"")*($Y$5:$Y$1004<$Y16))+SUMPRODUCT(($X$5:$X$1004<>"")*($Y$5:$Y$1004=$Y16)*($X$5:$X$1004<$X16))+1) | AA16: =IFERROR(MATCH(ROWS($AA$5:AA16),$Z$5:$Z$1004,0),"") | AB16: =IF($AA16="","",INDEX($X$5:$X$1004,$AA16))
... A1004: =IF($AB1004="","",INDEX('RobotLookup Clean'!$B:$B,$AB1004)) | B1004: =IF($AB1004="","",INDEX('RobotLookup Clean'!$D:$D,$AB1004)) | X1004: =IF(AND(INDEX('RobotLookup Clean'!$E:$E,ROW()-3)="Junior",INDEX('RobotLookup Clean'!$R:$R,ROW()-3)=1),ROW()-3,"") | Y1004: =IF($X1004="","",INDEX('RobotLookup Clean'!$B:$B,$X1004)) | Z1004: =IF($X1004="","",SUMPRODUCT(($X$5:$X$1004<>"")*($Y$5:$Y$1004<$Y1004))+SUMPRODUCT(($X$5:$X$1004<>"")*($Y$5:$Y$1004=$Y1004)*($X$5:$X$1004<$X1004))+1) | AA1004: =IFERROR(MATCH(ROWS($AA$5:AA1004),$Z$5:$Z$1004,0),"") | AB1004: =IF($AA1004="","",INDEX($X$5:$X$1004,$AA1004))

Sheet Senior Half Size Line Follower
A1: Senior Half Size Line Follower
A4: Robot Name | B4: Builder Name | C4: Run 1 | D4: Touch | E4: Run 2 | F4: Touch | G4: Run 3 | H4: Touch | I4: Best Run | J4: Position | K4: Notes | X4: Source Row | Y4: Robot Name | Z4: Sort Rank | AA4: Match Pos | AB4: Sorted Source Row
A5: =IF($AB5="","",INDEX('RobotLookup Clean'!$B:$B,$AB5)) -> Example Robot 04 | B5: =IF($AB5="","",INDEX('RobotLookup Clean'!$D:$D,$AB5)) -> Example Contestant 04 | X5: =IF(AND(INDEX('RobotLookup Clean'!$E:$E,ROW()-3)="Senior",INDEX('RobotLookup Clean'!$Z:$Z,ROW()-3)=1),ROW()-3,"") | Y5: =IF($X5="","",INDEX('RobotLookup Clean'!$B:$B,$X5)) | Z5: =IF($X5="","",SUMPRODUCT(($X$5:$X$1004<>"")*($Y$5:$Y$1004<$Y5))+SUMPRODUCT(($X$5:$X$1004<>"")*($Y$5:$Y$1004=$Y5)*($X$5:$X$1004<$X5))+1) | AA5: =IFERROR(MATCH(ROWS($AA$5:AA5),$Z$5:$Z$1004,0),"") -> 4 | AB5: =IF($AA5="","",INDEX($X$5:$X$1004,$AA5)) -> 5
A6: =IF($AB6="","",INDEX('RobotLookup Clean'!$B:$B,$AB6)) -> Example Robot 05 | B6: =IF($AB6="","",INDEX('RobotLookup Clean'!$D:$D,$AB6)) -> Example Contestant 05 | X6: =IF(AND(INDEX('RobotLookup Clean'!$E:$E,ROW()-3)="Senior",INDEX('RobotLookup Clean'!$Z:$Z,ROW()-3)=1),ROW()-3,"") | Y6: =IF($X6="","",INDEX('RobotLookup Clean'!$B:$B,$X6)) | Z6: =IF($X6="","",SUMPRODUCT(($X$5:$X$1004<>"")*($Y$5:$Y$1004<$Y6))+SUMPRODUCT(($X$5:$X$1004<>"")*($Y$5:$Y$1004=$Y6)*($X$5:$X$1004<$X6))+1) | AA6: =IFERROR(MATCH(ROWS($AA$5:AA6),$Z$5:$Z$1004,0),"") -> 5 | AB6: =IF($AA6="","",INDEX($X$5:$X$1004,$AA6)) -> 6
A7: =IF($AB7="","",INDEX('RobotLookup Clean'!$B:$B,$AB7)) -> Example Robot 06 | B7: =IF($AB7="","",INDEX('RobotLookup Clean'!$D:$D,$AB7)) -> Example Contestant 06 | X7: =IF(AND(INDEX('RobotLookup Clean'!$E:$E,ROW()-3)="Senior",INDEX('RobotLookup Clean'!$Z:$Z,ROW()-3)=1),ROW()-3,"") | Y7: =IF($X7="","",INDEX('RobotLookup Clean'!$B:$B,$X7)) | Z7: =IF($X7="","",SUMPRODUCT(($X$5:$X$1004<>"")*($Y$5:$Y$1004<$Y7))+SUMPRODUCT(($X$5:$X$1004<>"")*($Y$5:$Y$1004=$Y7)*($X$5:$X$1004<$X7))+1) | AA7: =IFERROR(MATCH(ROWS($AA$5:AA7),$Z$5:$Z$1004,0),"") -> 6 | AB7: =IF($AA7="","",INDEX($X$5:$X$1004,$AA7)) -> 7
A8: =IF($AB8="","",INDEX('RobotLookup Clean'!$B:$B,$AB8)) -> Example Robot 07 | B8: =IF($AB8="","",INDEX('RobotLookup Clean'!$D:$D,$AB8)) -> Example Contestant 07 | X8: =IF(AND(INDEX('RobotLookup Clean'!$E:$E,ROW()-3)="Senior",INDEX('RobotLookup Clean'!$Z:$Z,ROW()-3)=1),ROW()-3,"") -> 5 | Y8: =IF($X8="","",INDEX('RobotLookup Clean'!$B:$B,$X8)) -> Example Robot 04 | Z8: =IF($X8="","",SUMPRODUCT(($X$5:$X$1004<>"")*($Y$5:$Y$1004<$Y8))+SUMPRODUCT(($X$5:$X$1004<>"")*($Y$5:$Y$1004=$Y8)*($X$5:$X$1004<$X8))+1) -> 1 | AA8: =IFERROR(MATCH(ROWS($AA$5:AA8),$Z$5:$Z$1004,0),"") -> 7 | AB8: =IF($AA8="","",INDEX($X$5:$X$1004,$AA8)) -> 8
A9: =IF($AB9="","",INDEX('RobotLookup Clean'!$B:$B,$AB9)) -> Example Robot 08 | B9: =IF($AB9="","",INDEX('RobotLookup Clean'!$D:$D,$AB9)) -> Example Contestant 07 | X9: =IF(AND(INDEX('RobotLookup Clean'!$E:$E,ROW()-3)="Senior",INDEX('RobotLookup Clean'!$Z:$Z,ROW()-3)=1),ROW()-3,"") -> 6 | Y9: =IF($X9="","",INDEX('RobotLookup Clean'!$B:$B,$X9)) -> Example Robot 05 | Z9: =IF($X9="","",SUMPRODUCT(($X$5:$X$1004<>"")*($Y$5:$Y$1004<$Y9))+SUMPRODUCT(($X$5:$X$1004<>"")*($Y$5:$Y$1004=$Y9)*($X$5:$X$1004<$X9))+1) -> 2 | AA9: =IFERROR(MATCH(ROWS($AA$5:AA9),$Z$5:$Z$1004,0),"") -> 8 | AB9: =IF($AA9="","",INDEX($X$5:$X$1004,$AA9)) -> 9
A10: =IF($AB10="","",INDEX('RobotLookup Clean'!$B:$B,$AB10)) -> Example Robot 09 | B10: =IF($AB10="","",INDEX('RobotLookup Clean'!$D:$D,$AB10)) -> Example Contestant 08 | X10: =IF(AND(INDEX('RobotLookup Clean'!$E:$E,ROW()-3)="Senior",INDEX('RobotLookup Clean'!$Z:$Z,ROW()-3)=1),ROW()-3,"") -> 7 | Y10: =IF($X10="","",INDEX('RobotLookup Clean'!$B:$B,$X10)) -> Example Robot 06 | Z10: =IF($X10="","",SUMPRODUCT(($X$5:$X$1004<>"")*($Y$5:$Y$1004<$Y10))+SUMPRODUCT(($X$5:$X$1004<>"")*($Y$5:$Y$1004=$Y10)*($X$5:$X$1004<$X10))+1) -> 3 | AA10: =IFERROR(MATCH(ROWS($AA$5:AA10),$Z$5:$Z$1004,0),"") -> 9 | AB10: =IF($AA10="","",INDEX($X$5:$X$1004,$AA10)) -> 10
A11: =IF($AB11="","",INDEX('RobotLookup Clean'!$B:$B,$AB11)) -> Example Robot 10 | B11: =IF($AB11="","",INDEX('RobotLookup Clean'!$D:$D,$AB11)) -> Example Contestant 09 | X11: =IF(AND(INDEX('RobotLookup Clean'!$E:$E,ROW()-3)="Senior",INDEX('RobotLookup Clean'!$Z:$Z,ROW()-3)=1),ROW()-3,"") -> 8 | Y11: =IF($X11="","",INDEX('RobotLookup Clean'!$B:$B,$X11)) -> Example Robot 07 | Z11: =IF($X11="","",SUMPRODUCT(($X$5:$X$1004<>"")*($Y$5:$Y$1004<$Y11))+SUMPRODUCT(($X$5:$X$1004<>"")*($Y$5:$Y$1004=$Y11)*($X$5:$X$1004<$X11))+1) -> 4 | AA11: =IFERROR(MATCH(ROWS($AA$5:AA11),$Z$5:$Z$1004,0),"") -> 10 | AB11: =IF($AA11="","",INDEX($X$5:$X$1004,$AA11)) -> 11
A12: =IF($AB12="","",INDEX('RobotLookup Clean'!$B:$B,$AB12)) -> Example Robot 11 | B12: =IF($AB12="","",INDEX('RobotLookup Clean'!$D:$D,$AB12)) -> Example Contestant 09 | X12: =IF(AND(INDEX('RobotLookup Clean'!$E:$E,ROW()-3)="Senior",INDEX('RobotLookup Clean'!$Z:$Z,ROW()-3)=1),ROW()-3,"") -> 9 | Y12: =IF($X12="","",INDEX('RobotLookup Clean'!$B:$B,$X12)) -> Example Robot 08 | Z12: =IF($X12="","",SUMPRODUCT(($X$5:$X$1004<>"")*($Y$5:$Y$1004<$Y12))+SUMPRODUCT(($X$5:$X$1004<>"")*($Y$5:$Y$1004=$Y12)*($X$5:$X$1004<$X12))+1) -> 5 | AA12: =IFERROR(MATCH(ROWS($AA$5:AA12),$Z$5:$Z$1004,0),"") -> 11 | AB12: =IF($AA12="","",INDEX($X$5:$X$1004,$AA12)) -> 12
A13: =IF($AB13="","",INDEX('RobotLookup Clean'!$B:$B,$AB13)) -> Example Robot 12 | B13: =IF($AB13="","",INDEX('RobotLookup Clean'!$D:$D,$AB13)) -> Example Contestant 05 | X13: =IF(AND(INDEX('RobotLookup Clean'!$E:$E,ROW()-3)="Senior",INDEX('RobotLookup Clean'!$Z:$Z,ROW()-3)=1),ROW()-3,"") -> 10 | Y13: =IF($X13="","",INDEX('RobotLookup Clean'!$B:$B,$X13)) -> Example Robot 09 | Z13: =IF($X13="","",SUMPRODUCT(($X$5:$X$1004<>"")*($Y$5:$Y$1004<$Y13))+SUMPRODUCT(($X$5:$X$1004<>"")*($Y$5:$Y$1004=$Y13)*($X$5:$X$1004<$X13))+1) -> 6 | AA13: =IFERROR(MATCH(ROWS($AA$5:AA13),$Z$5:$Z$1004,0),"") -> 12 | AB13: =IF($AA13="","",INDEX($X$5:$X$1004,$AA13)) -> 13
A14: =IF($AB14="","",INDEX('RobotLookup Clean'!$B:$B,$AB14)) -> Example Robot 13 | B14: =IF($AB14="","",INDEX('RobotLookup Clean'!$D:$D,$AB14)) -> Example Contestant 10 | X14: =IF(AND(INDEX('RobotLookup Clean'!$E:$E,ROW()-3)="Senior",INDEX('RobotLookup Clean'!$Z:$Z,ROW()-3)=1),ROW()-3,"") -> 11 | Y14: =IF($X14="","",INDEX('RobotLookup Clean'!$B:$B,$X14)) -> Example Robot 10 | Z14: =IF($X14="","",SUMPRODUCT(($X$5:$X$1004<>"")*($Y$5:$Y$1004<$Y14))+SUMPRODUCT(($X$5:$X$1004<>"")*($Y$5:$Y$1004=$Y14)*($X$5:$X$1004<$X14))+1) -> 7 | AA14: =IFERROR(MATCH(ROWS($AA$5:AA14),$Z$5:$Z$1004,0),"") -> 13 | AB14: =IF($AA14="","",INDEX($X$5:$X$1004,$AA14)) -> 14
A15: =IF($AB15="","",INDEX('RobotLookup Clean'!$B:$B,$AB15)) -> Example Robot 14 | B15: =IF($AB15="","",INDEX('RobotLookup Clean'!$D:$D,$AB15)) -> Example Contestant 08 | X15: =IF(AND(INDEX('RobotLookup Clean'!$E:$E,ROW()-3)="Senior",INDEX('RobotLookup Clean'!$Z:$Z,ROW()-3)=1),ROW()-3,"") -> 12 | Y15: =IF($X15="","",INDEX('RobotLookup Clean'!$B:$B,$X15)) -> Example Robot 11 | Z15: =IF($X15="","",SUMPRODUCT(($X$5:$X$1004<>"")*($Y$5:$Y$1004<$Y15))+SUMPRODUCT(($X$5:$X$1004<>"")*($Y$5:$Y$1004=$Y15)*($X$5:$X$1004<$X15))+1) -> 8 | AA15: =IFERROR(MATCH(ROWS($AA$5:AA15),$Z$5:$Z$1004,0),"") -> 14 | AB15: =IF($AA15="","",INDEX($X$5:$X$1004,$AA15)) -> 15
A16: =IF($AB16="","",INDEX('RobotLookup Clean'!$B:$B,$AB16)) -> Example Robot 15 | B16: =IF($AB16="","",INDEX('RobotLookup Clean'!$D:$D,$AB16)) -> Example Contestant 10 | X16: =IF(AND(INDEX('RobotLookup Clean'!$E:$E,ROW()-3)="Senior",INDEX('RobotLookup Clean'!$Z:$Z,ROW()-3)=1),ROW()-3,"") -> 13 | Y16: =IF($X16="","",INDEX('RobotLookup Clean'!$B:$B,$X16)) -> Example Robot 12 | Z16: =IF($X16="","",SUMPRODUCT(($X$5:$X$1004<>"")*($Y$5:$Y$1004<$Y16))+SUMPRODUCT(($X$5:$X$1004<>"")*($Y$5:$Y$1004=$Y16)*($X$5:$X$1004<$X16))+1) -> 9 | AA16: =IFERROR(MATCH(ROWS($AA$5:AA16),$Z$5:$Z$1004,0),"") -> 15 | AB16: =IF($AA16="","",INDEX($X$5:$X$1004,$AA16)) -> 16
... A1004: =IF($AB1004="","",INDEX('RobotLookup Clean'!$B:$B,$AB1004)) | B1004: =IF($AB1004="","",INDEX('RobotLookup Clean'!$D:$D,$AB1004)) | X1004: =IF(AND(INDEX('RobotLookup Clean'!$E:$E,ROW()-3)="Senior",INDEX('RobotLookup Clean'!$Z:$Z,ROW()-3)=1),ROW()-3,"") | Y1004: =IF($X1004="","",INDEX('RobotLookup Clean'!$B:$B,$X1004)) | Z1004: =IF($X1004="","",SUMPRODUCT(($X$5:$X$1004<>"")*($Y$5:$Y$1004<$Y1004))+SUMPRODUCT(($X$5:$X$1004<>"")*($Y$5:$Y$1004=$Y1004)*($X$5:$X$1004<$X1004))+1) | AA1004: =IFERROR(MATCH(ROWS($AA$5:AA1004),$Z$5:$Z$1004,0),"") | AB1004: =IF($AA1004="","",INDEX($X$5:$X$1004,$AA1004))

Sheet Junior Half Size Wall Follower
A1: Junior Half Size Wall Follower
A4: Robot Name | B4: Builder Name | C4: Run 1 | D4: Touch | E4: Run 2 | F4: Touch | G4: Run 3 | H4: Touch | I4: Best Run | J4: Position | K4: Notes | X4: Source Row | Y4: Robot Name | Z4: Sort Rank | AA4: Match Pos | AB4: Sorted Source Row
A5: =IF($AB5="","",INDEX('RobotLookup Clean'!$B:$B,$AB5)) | B5: =IF($AB5="","",INDEX('RobotLookup Clean'!$D:$D,$AB5)) | X5: =IF(AND(INDEX('RobotLookup Clean'!$E:$E,ROW()-3)="Junior",INDEX('RobotLookup Clean'!$U:$U,ROW()-3)=1),ROW()-3,"") | Y5: =IF($X5="","",INDEX('RobotLookup Clean'!$B:$B,$X5)) | Z5: =IF($X5="","",SUMPRODUCT(($X$5:$X$1004<>"")*($Y$5:$Y$1004<$Y5))+SUMPRODUCT(($X$5:$X$1004<>"")*($Y$5:$Y$1004=$Y5)*($X$5:$X$1004<$X5))+1) | AA5: =IFERROR(MATCH(ROWS($AA$5:AA5),$Z$5:$Z$1004,0),"") | AB5: =IF($AA5="","",INDEX($X$5:$X$1004,$AA5))
A6: =IF($AB6="","",INDEX('RobotLookup Clean'!$B:$B,$AB6)) | B6: =IF($AB6="","",INDEX('RobotLookup Clean'!$D:$D,$AB6)) | X6: =IF(AND(INDEX('RobotLookup Clean'!$E:$E,ROW()-3)="Junior",INDEX('RobotLookup Clean'!$U:$U,ROW()-3)=1),ROW()-3,"") | Y6: =IF($X6="","",INDEX('RobotLookup Clean'!$B:$B,$X6)) | Z6: =IF($X6="","",SUMPRODUCT(($X$5:$X$1004<>"")*($Y$5:$Y$1004<$Y6))+SUMPRODUCT(($X$5:$X$1004<>"")*($Y$5:$Y$1004=$Y6)*($X$5:$X$1004<$X6))+1) | AA6: =IFERROR(MATCH(ROWS($AA$5:AA6),$Z$5:$Z$1004,0),"") | AB6: =IF($AA6="","",INDEX($X$5:$X$1004,$AA6))
A7: =IF($AB7="","",INDEX('RobotLookup Clean'!$B:$B,$AB7)) | B7: =IF($AB7="","",INDEX('RobotLookup Clean'!$D:$D,$AB7)) | X7: =IF(AND(INDEX('RobotLookup Clean'!$E:$E,ROW()-3)="Junior",INDEX('RobotLookup Clean'!$U:$U,ROW()-3)=1),ROW()-3,"") | Y7: =IF($X7="","",INDEX('RobotLookup Clean'!$B:$B,$X7)) | Z7: =IF($X7="","",SUMPRODUCT(($X$5:$X$1004<>"")*($Y$5:$Y$1004<$Y7))+SUMPRODUCT(($X$5:$X$1004<>"")*($Y$5:$Y$1004=$Y7)*($X$5:$X$1004<$X7))+1) | AA7: =IFERROR(MATCH(ROWS($AA$5:AA7),$Z$5:$Z$1004,0),"") | AB7: =IF($AA7="","",INDEX($X$5:$X$1004,$AA7))
A8: =IF($AB8="","",INDEX('RobotLookup Clean'!$B:$B,$AB8)) | B8: =IF($AB8="","",INDEX('RobotLookup Clean'!$D:$D,$AB8)) | X8: =IF(AND(INDEX('RobotLookup Clean'!$E:$E,ROW()-3)="Junior",INDEX('RobotLookup Clean'!$U:$U,ROW()-3)=1),ROW()-3,"") | Y8: =IF($X8="","",INDEX('RobotLookup Clean'!$B:$B,$X8)) | Z8: =IF($X8="","",SUMPRODUCT(($X$5:$X$1004<>"")*($Y$5:$Y$1004<$Y8))+SUMPRODUCT(($X$5:$X$1004<>"")*($Y$5:$Y$1004=$Y8)*($X$5:$X$1004<$X8))+1) | AA8: =IFERROR(MATCH(ROWS($AA$5:AA8),$Z$5:$Z$1004,0),"") | AB8: =IF($AA8="","",INDEX($X$5:$X$1004,$AA8))
A9: =IF($AB9="","",INDEX('RobotLookup Clean'!$B:$B,$AB9)) | B9: =IF($AB9="","",INDEX('RobotLookup Clean'!$D:$D,$AB9)) | X9: =IF(AND(INDEX('RobotLookup Clean'!$E:$E,ROW()-3)="Junior",INDEX('RobotLookup Clean'!$U:$U,ROW()-3)=1),ROW()-3,"") | Y9: =IF($X9="","",INDEX('RobotLookup Clean'!$B:$B,$X9)) | Z9: =IF($X9="","",SUMPRODUCT(($X$5:$X$1004<>"")*($Y$5:$Y$1004<$Y9))+SUMPRODUCT(($X$5:$X$1004<>"")*($Y$5:$Y$1004=$Y9)*($X$5:$X$1004<$X9))+1) | AA9: =IFERROR(MATCH(ROWS($AA$5:AA9),$Z$5:$Z$1004,0),"") | AB9: =IF($AA9="","",INDEX($X$5:$X$1004,$AA9))
A10: =IF($AB10="","",INDEX('RobotLookup Clean'!$B:$B,$AB10)) | B10: =IF($AB10="","",INDEX('RobotLookup Clean'!$D:$D,$AB10)) | X10: =IF(AND(INDEX('RobotLookup Clean'!$E:$E,ROW()-3)="Junior",INDEX('RobotLookup Clean'!$U:$U,ROW()-3)=1),ROW()-3,"") | Y10: =IF($X10="","",INDEX('RobotLookup Clean'!$B:$B,$X10)) | Z10: =IF($X10="","",SUMPRODUCT(($X$5:$X$1004<>"")*($Y$5:$Y$1004<$Y10))+SUMPRODUCT(($X$5:$X$1004<>"")*($Y$5:$Y$1004=$Y10)*($X$5:$X$1004<$X10))+1) | AA10: =IFERROR(MATCH(ROWS($AA$5:AA10),$Z$5:$Z$1004,0),"") | AB10: =IF($AA10="","",INDEX($X$5:$X$1004,$AA10))
